Workbook

Sheet 안내
A1: 부산광역시 유치원·어린이집·초등학교 현황
A2: 수집일: 2026-09-23
A4: ■ 시트 구성
A5: · 전체: 3개 유형 통합 목록 1,916곳 (원명/구분/홈페이지/전화/총 인원/나이별 인원 요약)
A6: · 구군별 요약: 구·군별 기관 수와 인원 (수식으로 각 시트 집계)
A7: · 유치원 379곳 — 만3·4·5세, 연령혼합반, 특수학급 원아수
A8: · 어린이집 1,217곳 — 만0~5세, 혼합반, 장애아반, 기타 현원
A9: · 초등학교 320곳 — 1~6학년, 특수·순회학급 학생수 (2026 공시 302곳 + 확인 필요 18곳, 목록 하단)
A11: ■ 출처
A12: · 유치원·어린이집 목록/전화/홈페이지: 유치원알리미 통합검색 (e-childschoolinfo.moe.go.kr, 부산광역시)
A13: · 유치원·어린이집 나이별 인원: 유치원알리미 비교 > 학급·교육 (연령별 학급 현황의 "현원")
A14: · 초등학교 목록/전화/홈페이지: 학교알리미 (schoolinfo.go.kr) 학교 기본정보
... A24: · 초등학교 중 2026 공시가 없는 학교는 폐교·통폐합(예: 좌천초·좌성초·신선초·봉삼초 등) 가능성이 높아 목록 하단에 두고 요약 집계에서 제외했습니다.

Sheet 구군별 요약
A1: 구/군 | B1: 유치원 수 | C1: 유치원 원아 | D1: 어린이집 수 | E1: 어린이집 현원 | F1: 초등학교 수 | G1: 초등 학생 | H1: 기관 합계 | I1: 인원 합계
A2: 강서구 | B2: =COUNTIFS(유치원!$D$2:$D$380,$A2) | C2: =SUMIFS(유치원!$N$2:$N$380,유치원!$D$2:$D$380,$A2) | D2: =COUNTIFS(어린이집!$D$2:$D$1218,$A2) | E2: =SUMIFS(어린이집!$T$2:$T$1218,어린이집!$D$2:$D$1218,$A2) | F2: =COUNTIFS(초등학교!$D$2:$D$321,$A2,초등학교!$H$2:$H$321,"2026") | G2: =SUMIFS(초등학교!$Q$2:$Q$321,초등학교!$D$2:$D$321,$A2,초등학교!$H$2:$H$321,"2026") | H2: =B2+D2+F2 | I2: =C2+E2+G2
A3: 금정구 | B3: =COUNTIFS(유치원!$D$2:$D$380,$A3) | C3: =SUMIFS(유치원!$N$2:$N$380,유치원!$D$2:$D$380,$A3) | D3: =COUNTIFS(어린이집!$D$2:$D$1218,$A3) | E3: =SUMIFS(어린이집!$T$2:$T$1218,어린이집!$D$2:$D$1218,$A3) | F3: =COUNTIFS(초등학교!$D$2:$D$321,$A3,초등학교!$H$2:$H$321,"2026") | G3: =SUMIFS(초등학교!$Q$2:$Q$321,초등학교!$D$2:$D$321,$A3,초등학교!$H$2:$H$321,"2026") | H3: =B3+D3+F3 | I3: =C3+E3+G3
A4: 기장군 | B4: =COUNTIFS(유치원!$D$2:$D$380,$A4) | C4: =SUMIFS(유치원!$N$2:$N$380,유치원!$D$2:$D$380,$A4) | D4: =COUNTIFS(어린이집!$D$2:$D$1218,$A4) | E4: =SUMIFS(어린이집!$T$2:$T$1218,어린이집!$D$2:$D$1218,$A4) | F4: =COUNTIFS(초등학교!$D$2:$D$321,$A4,초등학교!$H$2:$H$321,"2026") | G4: =SUMIFS(초등학교!$Q$2:$Q$321,초등학교!$D$2:$D$321,$A4,초등학교!$H$2:$H$321,"2026") | H4: =B4+D4+F4 | I4: =C4+E4+G4
A5: 남구 | B5: =COUNTIFS(유치원!$D$2:$D$380,$A5) | C5: =SUMIFS(유치원!$N$2:$N$380,유치원!$D$2:$D$380,$A5) | D5: =COUNTIFS(어린이집!$D$2:$D$1218,$A5) | E5: =SUMIFS(어린이집!$T$2:$T$1218,어린이집!$D$2:$D$1218,$A5) | F5: =COUNTIFS(초등학교!$D$2:$D$321,$A5,초등학교!$H$2:$H$321,"2026") | G5: =SUMIFS(초등학교!$Q$2:$Q$321,초등학교!$D$2:$D$321,$A5,초등학교!$H$2:$H$321,"2026") | H5: =B5+D5+F5 | I5: =C5+E5+G5
A6: 동구 | B6: =COUNTIFS(유치원!$D$2:$D$380,$A6) | C6: =SUMIFS(유치원!$N$2:$N$380,유치원!$D$2:$D$380,$A6) | D6: =COUNTIFS(어린이집!$D$2:$D$1218,$A6) | E6: =SUMIFS(어린이집!$T$2:$T$1218,어린이집!$D$2:$D$1218,$A6) | F6: =COUNTIFS(초등학교!$D$2:$D$321,$A6,초등학교!$H$2:$H$321,"2026") | G6: =SUMIFS(초등학교!$Q$2:$Q$321,초등학교!$D$2:$D$321,$A6,초등학교!$H$2:$H$321,"2026") | H6: =B6+D6+F6 | I6: =C6+E6+G6
A7: 동래구 | B7: =COUNTIFS(유치원!$D$2:$D$380,$A7) | C7: =SUMIFS(유치원!$N$2:$N$380,유치원!$D$2:$D$380,$A7) | D7: =COUNTIFS(어린이집!$D$2:$D$1218,$A7) | E7: =SUMIFS(어린이집!$T$2:$T$1218,어린이집!$D$2:$D$1218,$A7) | F7: =COUNTIFS(초등학교!$D$2:$D$321,$A7,초등학교!$H$2:$H$321,"2026") | G7: =SUMIFS(초등학교!$Q$2:$Q$321,초등학교!$D$2:$D$321,$A7,초등학교!$H$2:$H$321,"2026") | H7: =B7+D7+F7 | I7: =C7+E7+G7
A8: 부산진구 | B8: =COUNTIFS(유치원!$D$2:$D$380,$A8) | C8: =SUMIFS(유치원!$N$2:$N$380,유치원!$D$2:$D$380,$A8) | D8: =COUNTIFS(어린이집!$D$2:$D$1218,$A8) | E8: =SUMIFS(어린이집!$T$2:$T$1218,어린이집!$D$2:$D$1218,$A8) | F8: =COUNTIFS(초등학교!$D$2:$D$321,$A8,초등학교!$H$2:$H$321,"2026") | G8: =SUMIFS(초등학교!$Q$2:$Q$321,초등학교!$D$2:$D$321,$A8,초등학교!$H$2:$H$321,"2026") | H8: =B8+D8+F8 | I8: =C8+E8+G8
A9: 북구 | B9: =COUNTIFS(유치원!$D$2:$D$380,$A9) | C9: =SUMIFS(유치원!$N$2:$N$380,유치원!$D$2:$D$380,$A9) | D9: =COUNTIFS(어린이집!$D$2:$D$1218,$A9) | E9: =SUMIFS(어린이집!$T$2:$T$1218,어린이집!$D$2:$D$1218,$A9) | F9: =COUNTIFS(초등학교!$D$2:$D$321,$A9,초등학교!$H$2:$H$321,"2026") | G9: =SUMIFS(초등학교!$Q$2:$Q$321,초등학교!$D$2:$D$321,$A9,초등학교!$H$2:$H$321,"2026") | H9: =B9+D9+F9 | I9: =C9+E9+G9
A10: 사상구 | B10: =COUNTIFS(유치원!$D$2:$D$380,$A10) | C10: =SUMIFS(유치원!$N$2:$N$380,유치원!$D$2:$D$380,$A10) | D10: =COUNTIFS(어린이집!$D$2:$D$1218,$A10) | E10: =SUMIFS(어린이집!$T$2:$T$1218,어린이집!$D$2:$D$1218,$A10) | F10: =COUNTIFS(초등학교!$D$2:$D$321,$A10,초등학교!$H$2:$H$321,"2026") | G10: =SUMIFS(초등학교!$Q$2:$Q$321,초등학교!$D$2:$D$321,$A10,초등학교!$H$2:$H$321,"2026") | H10: =B10+D10+F10 | I10: =C10+E10+G10
A11: 사하구 | B11: =COUNTIFS(유치원!$D$2:$D$380,$A11) | C11: =SUMIFS(유치원!$N$2:$N$380,유치원!$D$2:$D$380,$A11) | D11: =COUNTIFS(어린이집!$D$2:$D$1218,$A11) | E11: =SUMIFS(어린이집!$T$2:$T$1218,어린이집!$D$2:$D$1218,$A11) | F11: =COUNTIFS(초등학교!$D$2:$D$321,$A11,초등학교!$H$2:$H$321,"2026") | G11: =SUMIFS(초등학교!$Q$2:$Q$321,초등학교!$D$2:$D$321,$A11,초등학교!$H$2:$H$321,"2026") | H11: =B11+D11+F11 | I11: =C11+E11+G11
A12: 서구 | B12: =COUNTIFS(유치원!$D$2:$D$380,$A12) | C12: =SUMIFS(유치원!$N$2:$N$380,유치원!$D$2:$D$380,$A12) | D12: =COUNTIFS(어린이집!$D$2:$D$1218,$A12) | E12: =SUMIFS(어린이집!$T$2:$T$1218,어린이집!$D$2:$D$1218,$A12) | F12: =COUNTIFS(초등학교!$D$2:$D$321,$A12,초등학교!$H$2:$H$321,"2026") | G12: =SUMIFS(초등학교!$Q$2:$Q$321,초등학교!$D$2:$D$321,$A12,초등학교!$H$2:$H$321,"2026") | H12: =B12+D12+F12 | I12: =C12+E12+G12
A13: 수영구 | B13: =COUNTIFS(유치원!$D$2:$D$380,$A13) | C13: =SUMIFS(유치원!$N$2:$N$380,유치원!$D$2:$D$380,$A13) | D13: =COUNTIFS(어린이집!$D$2:$D$1218,$A13) | E13: =SUMIFS(어린이집!$T$2:$T$1218,어린이집!$D$2:$D$1218,$A13) | F13: =COUNTIFS(초등학교!$D$2:$D$321,$A13,초등학교!$H$2:$H$321,"2026") | G13: =SUMIFS(초등학교!$Q$2:$Q$321,초등학교!$D$2:$D$321,$A13,초등학교!$H$2:$H$321,"2026") | H13: =B13+D13+F13 | I13: =C13+E13+G13
... A17: 해운대구 | B17: =COUNTIFS(유치원!$D$2:$D$380,$A17) | C17: =SUMIFS(유치원!$N$2:$N$380,유치원!$D$2:$D$380,$A17) | D17: =COUNTIFS(어린이집!$D$2:$D$1218,$A17) | E17: =SUMIFS(어린이집!$T$2:$T$1218,어린이집!$D$2:$D$1218,$A17) | F17: =COUNTIFS(초등학교!$D$2:$D$321,$A17,초등학교!$H$2:$H$321,"2026") | G17: =SUMIFS(초등학교!$Q$2:$Q$321,초등학교!$D$2:$D$321,$A17,초등학교!$H$2:$H$321,"2026") | H17: =B17+D17+F17 | I17: =C17+E17+G17
A18: 합계 | B18: =SUM(B2:B17) | C18: =SUM(C2:C17) | D18: =SUM(D2:D17) | E18: =SUM(E2:E17) | F18: =SUM(F2:F17) | G18: =SUM(G2:G17) | H18: =SUM(H2:H17) | I18: =SUM(I2:I17)
A20: ※ 초등학교 수·학생은 2026년 공시가 있는 학교만 집계(폐교·통폐합 추정 학교 제외). 인원은 각 시트의 합계 열을 참조합니다.

Sheet 전체
A1: 원명(학교명) | B1: 구분 | C1: 설립유형 | D1: 구/군 | E1: 주소 | F1: 공식 홈페이지 | G1: 전화번호 | H1: 총 인원(현원) | I1: 나이별 인원 요약
A2: 가락초등학교병설유치원 | B2: 유치원 | C2: 공립(병설) | D2: 강서구 | E2: 부산광역시 강서구 호계로 41 | F2: http://school.busanedu.net/garak-k/main.do | G2: 051-971-8930 | H2: =유치원!N2
A3: 강서유치원 | B3: 유치원 | C3: 공립(단설) | D3: 강서구 | E3: 부산광역시 강서구 에코델타4로 93 | F3: https://school.busanedu.net/gangseo-k | G3: 051-911-2004 | H3: =유치원!N3 | I3: 만3세 98 / 만4세 94 / 만5세 81 / 특수학급 1
A4: 기린유치원 | B4: 유치원 | C4: 사립(사인) | D4: 강서구 | E4: 부산광역시 강서구 과학산단로334번다길 59 | F4: https://school.busanedu.net/girin-k/ | G4: 051-941-7741 | H4: =유치원!N4 | I4: 만3세 26 / 만4세 13 / 만5세 26 / 연령혼합반 12
A5: 남명유치원 | B5: 유치원 | C5: 공립(단설) | D5: 강서구 | E5: 부산광역시 강서구 명지오션시티11로 132 | F5: http://school.busanedu.net/nammyeong-k | G5: 051-271-7667 | H5: =유치원!N5 | I5: 만3세 27 / 만4세 37 / 만5세 25 / 특수학급 2
A6: 녹산유치원 | B6: 유치원 | C6: 공립(단설) | D6: 강서구 | E6: 부산광역시 강서구 과학산단2로20번길 55 | F6: http://school.busanedu.net/noksan-k/ | G6: 051-790-2100 | H6: =유치원!N6 | I6: 만3세 23 / 만4세 36 / 만5세 49 / 특수학급 2
A7: 대저유치원 | B7: 유치원 | C7: 사립(사인) | D7: 강서구 | E7: 부산광역시 강서구 공항로767번나길 7 | F7: https://school.busanedu.net/Daejeo-k | G7: 051-973-4026 | H7: =유치원!N7 | I7: 만3세 32 / 만4세 22 / 만5세 32 / 연령혼합반 20
A8: 명원초등학교병설유치원 | B8: 유치원 | C8: 공립(병설) | D8: 강서구 | E8: 부산광역시 강서구 명지국제6로 147 | F8: http://school.busanedu.net/myoungwon-k | G8: 051-250-3400 | H8: =유치원!N8 | I8: 만3세 14 / 만4세 24 / 만5세 20
A9: 명일유치원 | B9: 유치원 | C9: 공립(단설) | D9: 강서구 | E9: 부산광역시 강서구 명지국제5로 170-5 | F9: https://school.busanedu.net/myeong1-k | G9: 051-290-3400 | H9: =유치원!N9 | I9: 만3세 27 / 만4세 31 / 만5세 38 / 특수학급 4
A10: 명지가온유치원 | B10: 유치원 | C10: 공립(단설) | D10: 강서구 | E10: 부산광역시 강서구 명지오션시티6로 69 | F10: https://school.busanedu.net/myeongjigaon-k/main.do | G10: 051-609-1500 | H10: =유치원!N10 | I10: 만3세 98 / 만4세 127 / 만5세 134 / 특수학급 9
A11: 명지국제유치원 | B11: 유치원 | C11: 사립(사인) | D11: 강서구 | E11: 부산광역시 강서구 명지국제7로 186 | G11: 051-293-7722 | H11: =유치원!N11 | I11: 만3세 48 / 만4세 162 / 만5세 77 / 연령혼합반 162
A12: 명지꿈자람유치원 | B12: 유치원 | C12: 공립(단설) | D12: 강서구 | E12: 부산광역시 강서구 명지국제8로 199 | F12: https://school.busanedu.net/myungjidream-k/main.do | G12: 051-609-1900 | H12: =유치원!N12 | I12: 만3세 56 / 만4세 76 / 만5세 79
A13: 명지배화유치원 | B13: 유치원 | C13: 사립(사인) | D13: 강서구 | E13: 부산광역시 강서구 영강길 165 | F13: https://school.busanedu.net/mjbaewha-k | G13: 051-714-1902 | H13: =유치원!N13 | I13: 만3세 64 / 만4세 96 / 만5세 104
A14: 명지센텀유치원 | B14: 유치원 | C14: 사립(사인) | D14: 강서구 | E14: 부산광역시 강서구 명지오션시티9로 53 | G14: 051-714-2000 | H14: =유치원!N14 | I14: 연령혼합반 314
A15: 명지유치원 | B15: 유치원 | C15: 공립(단설) | D15: 강서구 | E15: 부산광역시 강서구 명지국제6로 296 | F15: http://school.busanedu.net/myungji-k/main.do | G15: 051-203-4890 | H15: =유치원!N15 | I15: 만3세 28 / 만4세 18 / 만5세 38 / 특수학급 3
A16: 명지자연유치원 | B16: 유치원 | C16: 사립(사인) | D16: 강서구 | E16: 부산광역시 강서구 신호산단1로140번길 16-3 | G16: 051-893-6677 | H16: =유치원!N16 | I16: 만3세 48 / 만4세 58 / 만5세 76
A17: 명호초등학교병설유치원 | B17: 유치원 | C17: 공립(병설) | D17: 강서구 | E17: 부산광역시 강서구 명지오션시티2로 41 | F17: http://school.busanedu.net/myungho-k/main.do | G17: 051-220-1190 | H17: =유치원!N17 | I17: 만5세 13 / 연령혼합반 10
A18: 보광유치원 | B18: 유치원 | C18: 사립(사인) | D18: 강서구 | E18: 부산광역시 강서구 공항진입로 28 | F18: http://school.busanedu.net/BoGwang-k | G18: 0519732242 | H18: =유치원!N18 | I18: 만3세 48 / 만4세 60 / 만5세 63 / 연령혼합반 22
A19: 새결유치원 | B19: 유치원 | C19: 공립(단설) | D19: 강서구 | E19: 부산광역시 강서구 에코평강길 91 | F19: https://school.busanedu.net/saegyeol-k/main.do | G19: 051-832-0175 | H19: =유치원!N19 | I19: 만3세 30 / 만4세 30 / 만5세 26 / 특수학급 11
A20: 송정유치원 | B20: 유치원 | C20: 공립(단설) | D20: 강서구 | E20: 부산광역시 강서구 신호사로 10 | F20: http://school.busanedu.net/sjkids-k | G20: 051-832-1390 | H20: =유치원!N20 | I20: 만3세 18 / 만4세 29 / 만5세 27 / 특수학급 4
A21: 신명유치원 | B21: 유치원 | C21: 공립(단설) | D21: 강서구 | E21: 부산광역시 강서구 명지국제7로 178 | F21: http://school.busanedu.net/smkids-k/main.do | G21: 051-293-6622 | H21: =유치원!N21 | I21: 만3세 28 / 만4세 34 / 만5세 17 / 특수학급 4
A22: 신호초등학교병설유치원 | B22: 유치원 | C22: 공립(병설) | D22: 강서구 | E22: 부산광역시 강서구 신호이로75번길 12 | F22: http://school.busanedu.net/shinho-k/main.do | G22: 051-974-6870 | H22: =유치원!N22 | I22: 만5세 8 / 연령혼합반 9
A23: 여울유치원 | B23: 유치원 | C23: 공립(단설) | D23: 강서구 | E23: 부산광역시 강서구 에코델타2로 13 | F23: https://school.busanedu.net/yeoul-k/main.do | G23: 051-709-1100 | H23: =유치원!N23 | I23: 만3세 70 / 만4세 89 / 만5세 98 / 특수학급 8
A24: 오션유치원 | B24: 유치원 | C24: 공립(단설) | D24: 강서구 | E24: 부산광역시 강서구 명지오션시티6로 72 | F24: http://school.busanedu.net/oceankids-k/main.do | G24: 051-201-5413 | H24: =유치원!N24 | I24: 만3세 39 / 만4세 37 / 만5세 59 / 특수학급 3
A25: 천가초등학교병설유치원 | B25: 유치원 | C25: 공립(병설) | D25: 강서구 | E25: 부산광역시 강서구 동선길 135 | F25: https://school.busanedu.net/chunga-k | G25: 051-972-7770 | H25: =유치원!N25 | I25: 연령혼합반 2
A26: 구서초등학교병설유치원 | B26: 유치원 | C26: 공립(병설) | D26: 금정구 | E26: 부산광역시 금정구 구서중앙로 35 | F26: http://school.busanedu.net/kuseo-k/ | G26: 051-996-4815 | H26: =유치원!N26 | I26: 만3세 4 / 만4세 14 / 만5세 17
A27: 금사초등학교병설유치원 | B27: 유치원 | C27: 공립(병설) | D27: 금정구 | E27: 부산광역시 금정구 금사로57번길 24 | F27: http://school.busanedu.net/kumsa-k | G27: 051-525-3134 | H27: =유치원!N27 | I27: 만5세 5 / 연령혼합반 11 / 특수학급 6
A28: 금샘누리유치원 | B28: 유치원 | C28: 공립(단설) | D28: 금정구 | E28: 부산광역시 금정구 금샘로 525 | F28: https://school.busanedu.net/geumsaem-k | G28: 051-968-9300 | H28: =유치원!N28 | I28: 만3세 11 / 만4세 27 / 만5세 25 / 특수학급 7
A29: 금정유치원 | B29: 유치원 | C29: 공립(단설) | D29: 금정구 | E29: 부산광역시 금정구 식물원로44번길 46 | F29: http://school.busanedu.net/guemjung-k | G29: 051-581-5488 | H29: =유치원!N29 | I29: 만3세 28 / 만4세 36 / 만5세 54 / 특수학급 4
A30: 꾸미랑유치원 | B30: 유치원 | C30: 사립(사인) | D30: 금정구 | E30: 부산광역시 금정구 서동로34번길 25 | G30: 051-581-2396 | H30: =유치원!N30 | I30: 만3세 23 / 만4세 23 / 만5세 13
A31: 대우유치원 | B31: 유치원 | C31: 사립(사인) | D31: 금정구 | E31: 부산광역시 금정구 부산대학로 10 | F31: http://school.busanedu.net/deawu-k | G31: 051-513-2888 | H31: =유치원!N31 | I31: 만4세 23 / 만5세 25 / 연령혼합반 17
A32: 동래초등학교부속유치원 | B32: 유치원 | C32: 사립(법인) | D32: 금정구 | E32: 부산광역시 금정구 체육공원로44번길 26 | F32: https://school.busanedu.net/dongraekg-k/main.do | G32: 051-515-2689 | H32: =유치원!N32 | I32: 만3세 48 / 만4세 48 / 만5세 50
A33: 동백유치원 | B33: 유치원 | C33: 사립(사인) | D33: 금정구 | E33: 부산광역시 금정구 수림로50번길 47 | F33: http://www.cafe.daum.net/db0610 | G33: 051-581-0610 | H33: =유치원!N33 | I33: 만4세 24 / 만5세 50 / 연령혼합반 87
A34: 둥지유치원 | B34: 유치원 | C34: 사립(사인) | D34: 금정구 | E34: 부산광역시 금정구 서동로103번길 78 | G34: 051-523-0365 | H34: =유치원!N34
A35: 미래자연유치원 | B35: 유치원 | C35: 사립(사인) | D35: 금정구 | E35: 부산광역시 금정구 청룡로61번길 34 | G35: 051-517-6786 | H35: =유치원!N35
A36: 삼광사부설광명유치원 | B36: 유치원 | C36: 사립(법인) | D36: 금정구 | E36: 부산광역시 금정구 금샘로 51 | F36: http://school.busanedu.net/kwangmyoung-k | G36: 051-512-4112 | H36: =유치원!N36 | I36: 만3세 78 / 만4세 78 / 만5세 91
A37: 서명초등학교병설유치원 | B37: 유치원 | C37: 공립(병설) | D37: 금정구 | E37: 부산광역시 금정구 명서로 48 | F37: http://school.busanedu.net/seomyeong-k | G37: 051-526-1670 | H37: =유치원!N37 | I37: 만3세 6 / 만4세 12 / 만5세 8 / 특수학급 4
A38: 소심유치원 | B38: 유치원 | C38: 사립(사인) | D38: 금정구 | E38: 부산광역시 금정구 동현로 76 | F38: http://school.busanedu.net/sosim-k | G38: 051-512-5617 | H38: =유치원!N38 | I38: 만3세 48 / 만4세 65 / 만5세 47
A39: 아람유치원 | B39: 유치원 | C39: 사립(사인) | D39: 금정구 | E39: 부산광역시 금정구 두실로15번길 52-13 | G39: 051-512-3111 | H39: =유치원!N39 | I39: 만4세 46 / 만5세 44 / 연령혼합반 44
A40: 아인유치원 | B40: 유치원 | C40: 사립(사인) | D40: 금정구 | E40: 부산광역시 금정구 금정도서관로 5-4 | F40: https://school.busanedu.net/ain-k/main.do | G40: 051-508-0004 | H40: =유치원!N40 | I40: 만4세 48 / 만5세 49 / 연령혼합반 68
...

Sheet 유치원
A1: 원명 | B1: 구분 | C1: 설립유형 | D1: 구/군 | E1: 주소 | F1: 공식 홈페이지 | G1: 전화번호 | H1: 정원 | I1: 만3세 | J1: 만4세 | K1: 만5세 | L1: 연령혼합반 | M1: 특수학급 | N1: 현원 합계 | O1: 비고
A2: 가락초등학교병설유치원 | B2: 유치원 | C2: 공립(병설) | D2: 강서구 | E2: 부산광역시 강서구 호계로 41 | F2: http://school.busanedu.net/garak-k/main.do | G2: 051-971-8930 | N2: =IF(COUNT(I2:M2)=0,"",SUM(I2:M2)) | O2: 연령별 현원 미공시(휴원·신설 등)
A3: 강서유치원 | B3: 유치원 | C3: 공립(단설) | D3: 강서구 | E3: 부산광역시 강서구 에코델타4로 93 | F3: https://school.busanedu.net/gangseo-k | G3: 051-911-2004 | H3: 273 | I3: 98 | J3: 94 | K3: 81 | L3: 0 | M3: 1 | N3: =IF(COUNT(I3:M3)=0,"",SUM(I3:M3))
A4: 기린유치원 | B4: 유치원 | C4: 사립(사인) | D4: 강서구 | E4: 부산광역시 강서구 과학산단로334번다길 59 | F4: https://school.busanedu.net/girin-k/ | G4: 051-941-7741 | H4: 231 | I4: 26 | J4: 13 | K4: 26 | L4: 12 | M4: 0 | N4: =IF(COUNT(I4:M4)=0,"",SUM(I4:M4))
A5: 남명유치원 | B5: 유치원 | C5: 공립(단설) | D5: 강서구 | E5: 부산광역시 강서구 명지오션시티11로 132 | F5: http://school.busanedu.net/nammyeong-k | G5: 051-271-7667 | H5: 106 | I5: 27 | J5: 37 | K5: 25 | L5: 0 | M5: 2 | N5: =IF(COUNT(I5:M5)=0,"",SUM(I5:M5))
A6: 녹산유치원 | B6: 유치원 | C6: 공립(단설) | D6: 강서구 | E6: 부산광역시 강서구 과학산단2로20번길 55 | F6: http://school.busanedu.net/noksan-k/ | G6: 051-790-2100 | H6: 126 | I6: 23 | J6: 36 | K6: 49 | L6: 0 | M6: 2 | N6: =IF(COUNT(I6:M6)=0,"",SUM(I6:M6))
A7: 대저유치원 | B7: 유치원 | C7: 사립(사인) | D7: 강서구 | E7: 부산광역시 강서구 공항로767번나길 7 | F7: https://school.busanedu.net/Daejeo-k | G7: 051-973-4026 | H7: 155 | I7: 32 | J7: 22 | K7: 32 | L7: 20 | M7: 0 | N7: =IF(COUNT(I7:M7)=0,"",SUM(I7:M7))
A8: 명원초등학교병설유치원 | B8: 유치원 | C8: 공립(병설) | D8: 강서구 | E8: 부산광역시 강서구 명지국제6로 147 | F8: http://school.busanedu.net/myoungwon-k | G8: 051-250-3400 | H8: 72 | I8: 14 | J8: 24 | K8: 20 | L8: 0 | M8: 0 | N8: =IF(COUNT(I8:M8)=0,"",SUM(I8:M8))
A9: 명일유치원 | B9: 유치원 | C9: 공립(단설) | D9: 강서구 | E9: 부산광역시 강서구 명지국제5로 170-5 | F9: https://school.busanedu.net/myeong1-k | G9: 051-290-3400 | H9: 106 | I9: 27 | J9: 31 | K9: 38 | L9: 0 | M9: 4 | N9: =IF(COUNT(I9:M9)=0,"",SUM(I9:M9))
A10: 명지가온유치원 | B10: 유치원 | C10: 공립(단설) | D10: 강서구 | E10: 부산광역시 강서구 명지오션시티6로 69 | F10: https://school.busanedu.net/myeongjigaon-k/main.do | G10: 051-609-1500 | H10: 371 | I10: 98 | J10: 127 | K10: 134 | L10: 0 | M10: 9 | N10: =IF(COUNT(I10:M10)=0,"",SUM(I10:M10))
A11: 명지국제유치원 | B11: 유치원 | C11: 사립(사인) | D11: 강서구 | E11: 부산광역시 강서구 명지국제7로 186 | G11: 051-293-7722 | H11: 496 | I11: 48 | J11: 162 | K11: 77 | L11: 162 | M11: 0 | N11: =IF(COUNT(I11:M11)=0,"",SUM(I11:M11))
A12: 명지꿈자람유치원 | B12: 유치원 | C12: 공립(단설) | D12: 강서구 | E12: 부산광역시 강서구 명지국제8로 199 | F12: https://school.busanedu.net/myungjidream-k/main.do | G12: 051-609-1900 | H12: 212 | I12: 56 | J12: 76 | K12: 79 | L12: 0 | M12: 0 | N12: =IF(COUNT(I12:M12)=0,"",SUM(I12:M12))
A13: 명지배화유치원 | B13: 유치원 | C13: 사립(사인) | D13: 강서구 | E13: 부산광역시 강서구 영강길 165 | F13: https://school.busanedu.net/mjbaewha-k | G13: 051-714-1902 | H13: 306 | I13: 64 | J13: 96 | K13: 104 | L13: 0 | M13: 0 | N13: =IF(COUNT(I13:M13)=0,"",SUM(I13:M13))
A14: 명지센텀유치원 | B14: 유치원 | C14: 사립(사인) | D14: 강서구 | E14: 부산광역시 강서구 명지오션시티9로 53 | G14: 051-714-2000 | H14: 318 | I14: 0 | J14: 0 | K14: 0 | L14: 314 | M14: 0 | N14: =IF(COUNT(I14:M14)=0,"",SUM(I14:M14))
A15: 명지유치원 | B15: 유치원 | C15: 공립(단설) | D15: 강서구 | E15: 부산광역시 강서구 명지국제6로 296 | F15: http://school.busanedu.net/myungji-k/main.do | G15: 051-203-4890 | H15: 87 | I15: 28 | J15: 18 | K15: 38 | L15: 0 | M15: 3 | N15: =IF(COUNT(I15:M15)=0,"",SUM(I15:M15))
A16: 명지자연유치원 | B16: 유치원 | C16: 사립(사인) | D16: 강서구 | E16: 부산광역시 강서구 신호산단1로140번길 16-3 | G16: 051-893-6677 | H16: 568 | I16: 48 | J16: 58 | K16: 76 | L16: 0 | M16: 0 | N16: =IF(COUNT(I16:M16)=0,"",SUM(I16:M16))
A17: 명호초등학교병설유치원 | B17: 유치원 | C17: 공립(병설) | D17: 강서구 | E17: 부산광역시 강서구 명지오션시티2로 41 | F17: http://school.busanedu.net/myungho-k/main.do | G17: 051-220-1190 | H17: 37 | I17: 0 | J17: 0 | K17: 13 | L17: 10 | M17: 0 | N17: =IF(COUNT(I17:M17)=0,"",SUM(I17:M17))
A18: 보광유치원 | B18: 유치원 | C18: 사립(사인) | D18: 강서구 | E18: 부산광역시 강서구 공항진입로 28 | F18: http://school.busanedu.net/BoGwang-k | G18: 0519732242 | H18: 242 | I18: 48 | J18: 60 | K18: 63 | L18: 22 | M18: 0 | N18: =IF(COUNT(I18:M18)=0,"",SUM(I18:M18))
A19: 새결유치원 | B19: 유치원 | C19: 공립(단설) | D19: 강서구 | E19: 부산광역시 강서구 에코평강길 91 | F19: https://school.busanedu.net/saegyeol-k/main.do | G19: 051-832-0175 | H19: 116 | I19: 30 | J19: 30 | K19: 26 | L19: 0 | M19: 11 | N19: =IF(COUNT(I19:M19)=0,"",SUM(I19:M19))
A20: 송정유치원 | B20: 유치원 | C20: 공립(단설) | D20: 강서구 | E20: 부산광역시 강서구 신호사로 10 | F20: http://school.busanedu.net/sjkids-k | G20: 051-832-1390 | H20: 106 | I20: 18 | J20: 29 | K20: 27 | L20: 0 | M20: 4 | N20: =IF(COUNT(I20:M20)=0,"",SUM(I20:M20))
A21: 신명유치원 | B21: 유치원 | C21: 공립(단설) | D21: 강서구 | E21: 부산광역시 강서구 명지국제7로 178 | F21: http://school.busanedu.net/smkids-k/main.do | G21: 051-293-6622 | H21: 86 | I21: 28 | J21: 34 | K21: 17 | L21: 0 | M21: 4 | N21: =IF(COUNT(I21:M21)=0,"",SUM(I21:M21))
A22: 신호초등학교병설유치원 | B22: 유치원 | C22: 공립(병설) | D22: 강서구 | E22: 부산광역시 강서구 신호이로75번길 12 | F22: http://school.busanedu.net/shinho-k/main.do | G22: 051-974-6870 | H22: 37 | I22: 0 | J22: 0 | K22: 8 | L22: 9 | M22: 0 | N22: =IF(COUNT(I22:M22)=0,"",SUM(I22:M22))
A23: 여울유치원 | B23: 유치원 | C23: 공립(단설) | D23: 강서구 | E23: 부산광역시 강서구 에코델타2로 13 | F23: https://school.busanedu.net/yeoul-k/main.do | G23: 051-709-1100 | H23: 265 | I23: 70 | J23: 89 | K23: 98 | L23: 0 | M23: 8 | N23: =IF(COUNT(I23:M23)=0,"",SUM(I23:M23))
A24: 오션유치원 | B24: 유치원 | C24: 공립(단설) | D24: 강서구 | E24: 부산광역시 강서구 명지오션시티6로 72 | F24: http://school.busanedu.net/oceankids-k/main.do | G24: 051-201-5413 | H24: 140 | I24: 39 | J24: 37 | K24: 59 | L24: 0 | M24: 3 | N24: =IF(COUNT(I24:M24)=0,"",SUM(I24:M24))
A25: 천가초등학교병설유치원 | B25: 유치원 | C25: 공립(병설) | D25: 강서구 | E25: 부산광역시 강서구 동선길 135 | F25: https://school.busanedu.net/chunga-k | G25: 051-972-7770 | H25: 17 | I25: 0 | J25: 0 | K25: 0 | L25: 2 | M25: 0 | N25: =IF(COUNT(I25:M25)=0,"",SUM(I25:M25))
A26: 구서초등학교병설유치원 | B26: 유치원 | C26: 공립(병설) | D26: 금정구 | E26: 부산광역시 금정구 구서중앙로 35 | F26: http://school.busanedu.net/kuseo-k/ | G26: 051-996-4815 | H26: 53 | I26: 4 | J26: 14 | K26: 17 | L26: 0 | M26: 0 | N26: =IF(COUNT(I26:M26)=0,"",SUM(I26:M26))
A27: 금사초등학교병설유치원 | B27: 유치원 | C27: 공립(병설) | D27: 금정구 | E27: 부산광역시 금정구 금사로57번길 24 | F27: http://school.busanedu.net/kumsa-k | G27: 051-525-3134 | H27: 37 | I27: 0 | J27: 0 | K27: 5 | L27: 11 | M27: 6 | N27: =IF(COUNT(I27:M27)=0,"",SUM(I27:M27))
A28: 금샘누리유치원 | B28: 유치원 | C28: 공립(단설) | D28: 금정구 | E28: 부산광역시 금정구 금샘로 525 | F28: https://school.busanedu.net/geumsaem-k | G28: 051-968-9300 | H28: 92 | I28: 11 | J28: 27 | K28: 25 | L28: 0 | M28: 7 | N28: =IF(COUNT(I28:M28)=0,"",SUM(I28:M28))
A29: 금정유치원 | B29: 유치원 | C29: 공립(단설) | D29: 금정구 | E29: 부산광역시 금정구 식물원로44번길 46 | F29: http://school.busanedu.net/guemjung-k | G29: 051-581-5488 | H29: 126 | I29: 28 | J29: 36 | K29: 54 | L29: 0 | M29: 4 | N29: =IF(COUNT(I29:M29)=0,"",SUM(I29:M29))
A30: 꾸미랑유치원 | B30: 유치원 | C30: 사립(사인) | D30: 금정구 | E30: 부산광역시 금정구 서동로34번길 25 | G30: 051-581-2396 | H30: 100 | I30: 23 | J30: 23 | K30: 13 | L30: 0 | M30: 0 | N30: =IF(COUNT(I30:M30)=0,"",SUM(I30:M30))
A31: 대우유치원 | B31: 유치원 | C31: 사립(사인) | D31: 금정구 | E31: 부산광역시 금정구 부산대학로 10 | F31: http://school.busanedu.net/deawu-k | G31: 051-513-2888 | H31: 82 | I31: 0 | J31: 23 | K31: 25 | L31: 17 | M31: 0 | N31: =IF(COUNT(I31:M31)=0,"",SUM(I31:M31))
A32: 동래초등학교부속유치원 | B32: 유치원 | C32: 사립(법인) | D32: 금정구 | E32: 부산광역시 금정구 체육공원로44번길 26 | F32: https://school.busanedu.net/dongraekg-k/main.do | G32: 051-515-2689 | H32: 172 | I32: 48 | J32: 48 | K32: 50 | L32: 0 | M32: 0 | N32: =IF(COUNT(I32:M32)=0,"",SUM(I32:M32))
A33: 동백유치원 | B33: 유치원 | C33: 사립(사인) | D33: 금정구 | E33: 부산광역시 금정구 수림로50번길 47 | F33: http://www.cafe.daum.net/db0610 | G33: 051-581-0610 | H33: 174 | I33: 0 | J33: 24 | K33: 50 | L33: 87 | M33: 0 | N33: =IF(COUNT(I33:M33)=0,"",SUM(I33:M33))
A34: 둥지유치원 | B34: 유치원 | C34: 사립(사인) | D34: 금정구 | E34: 부산광역시 금정구 서동로103번길 78 | G34: 051-523-0365 | N34: =IF(COUNT(I34:M34)=0,"",SUM(I34:M34)) | O34: 연령별 현원 미공시(휴원·신설 등)
A35: 미래자연유치원 | B35: 유치원 | C35: 사립(사인) | D35: 금정구 | E35: 부산광역시 금정구 청룡로61번길 34 | G35: 051-517-6786 | N35: =IF(COUNT(I35:M35)=0,"",SUM(I35:M35)) | O35: 연령별 현원 미공시(휴원·신설 등)
A36: 삼광사부설광명유치원 | B36: 유치원 | C36: 사립(법인) | D36: 금정구 | E36: 부산광역시 금정구 금샘로 51 | F36: http://school.busanedu.net/kwangmyoung-k | G36: 051-512-4112 | H36: 400 | I36: 78 | J36: 78 | K36: 91 | L36: 0 | M36: 0 | N36: =IF(COUNT(I36:M36)=0,"",SUM(I36:M36))
A37: 서명초등학교병설유치원 | B37: 유치원 | C37: 공립(병설) | D37: 금정구 | E37: 부산광역시 금정구 명서로 48 | F37: http://school.busanedu.net/seomyeong-k | G37: 051-526-1670 | H37: 53 | I37: 6 | J37: 12 | K37: 8 | L37: 0 | M37: 4 | N37: =IF(COUNT(I37:M37)=0,"",SUM(I37:M37))
A38: 소심유치원 | B38: 유치원 | C38: 사립(사인) | D38: 금정구 | E38: 부산광역시 금정구 동현로 76 | F38: http://school.busanedu.net/sosim-k | G38: 051-512-5617 | H38: 198 | I38: 48 | J38: 65 | K38: 47 | L38: 0 | M38: 0 | N38: =IF(COUNT(I38:M38)=0,"",SUM(I38:M38))
A39: 아람유치원 | B39: 유치원 | C39: 사립(사인) | D39: 금정구 | E39: 부산광역시 금정구 두실로15번길 52-13 | G39: 051-512-3111 | H39: 174 | I39: 0 | J39: 46 | K39: 44 | L39: 44 | M39: 0 | N39: =IF(COUNT(I39:M39)=0,"",SUM(I39:M39))
A40: 아인유치원 | B40: 유치원 | C40: 사립(사인) | D40: 금정구 | E40: 부산광역시 금정구 금정도서관로 5-4 | F40: https://school.busanedu.net/ain-k/main.do | G40: 051-508-0004 | H40: 194 | I40: 0 | J40: 48 | K40: 49 | L40: 68 | M40: 0 | N40: =IF(COUNT(I40:M40)=0,"",SUM(I40:M40))
...

Sheet 어린이집
A1: 원명 | B1: 구분 | C1: 설립유형 | D1: 구/군 | E1: 주소 | F1: 공식 홈페이지 | G1: 전화번호 | H1: 정원 | I1: 만0세 | J1: 만1세 | K1: 만2세 | L1: 만3세 | M1: 만4세 | N1: 만5세 | O1: 영아혼합반 | P1: 유아혼합반 | Q1: 영유아혼합반 | R1: 장애아반(특수) | S1: 기타(연령구분 없음) | T1: 현원 합계 | U1: 비고
A2: KR 단미래 어린이집 | B2: 어린이집 | C2: 직장 | D2: 강서구 | E2: 부산광역시 강서구 명지오션시티9로 36 | G2: 070-8799-8170 | H2: 155 | I2: 0 | J2: 11 | K2: 8 | L2: 11 | M2: 21 | N2: 14 | O2: 0 | P2: 0 | Q2: 0 | R2: 0 | S2: 56 | T2: =IF(COUNT(I2:S2)=0,"",SUM(I2:S2))
A3: PNC어린이집 | B3: 어린이집 | C3: 직장 | D3: 강서구 | E3: 부산광역시 강서구 신항남로 372 | G3: 070-4145-5327 | H3: 20 | I3: 0 | J3: 0 | K3: 0 | L3: 0 | M3: 0 | N3: 0 | O3: 2 | P3: 0 | Q3: 0 | R3: 0 | S3: 0 | T3: =IF(COUNT(I3:S3)=0,"",SUM(I3:S3))
A4: 가온어린이집 | B4: 어린이집 | C4: 가정 | D4: 강서구 | E4: 부산광역시 강서구 명지국제7로 111 101동 101호(명지동, 명지더웨스턴) | G4: 051-201-3811 | H4: 20 | I4: 4 | J4: 5 | K4: 0 | L4: 0 | M4: 0 | N4: 0 | O4: 0 | P4: 0 | Q4: 0 | R4: 0 | S4: 0 | T4: =IF(COUNT(I4:S4)=0,"",SUM(I4:S4))
A5: 강변어린이집 | B5: 어린이집 | C5: 사회복지법인 | D5: 강서구 | E5: 부산광역시 강서구 공항로361번길 26 (대저2동) | G5: 051-971-0695 | H5: 129 | I5: 0 | J5: 0 | K5: 0 | L5: 0 | M5: 0 | N5: 0 | O5: 0 | P5: 0 | Q5: 0 | R5: 0 | S5: 0 | T5: =IF(COUNT(I5:S5)=0,"",SUM(I5:S5))
A6: 강서다온어린이집 | B6: 어린이집 | C6: 국공립 | D6: 강서구 | E6: 부산광역시 강서구 명지국제6로318번길 58 (명지동) | F6: https://m.cafe.naver.com/ca-fe/gangseodaon | G6: 051-203-3690 | H6: 79 | I6: 0 | J6: 10 | K6: 14 | L6: 24 | M6: 0 | N6: 8 | O6: 0 | P6: 0 | Q6: 0 | R6: 0 | S6: 17 | T6: =IF(COUNT(I6:S6)=0,"",SUM(I6:S6))
A7: 강서어린이집 | B7: 어린이집 | C7: 국공립 | D7: 강서구 | E7: 부산광역시 강서구 대저로63번길 31 (대저1동) | G7: 051-941-4591 | H7: 89 | I7: 9 | J7: 8 | K7: 17 | L7: 6 | M7: 0 | N7: 0 | O7: 0 | P7: 10 | Q7: 0 | R7: 2 | S7: 16 | T7: =IF(COUNT(I7:S7)=0,"",SUM(I7:S7))
A8: 강서자이어린이집 | B8: 어린이집 | C8: 국공립 | D8: 강서구 | E8: 부산광역시 강서구 에코델타1로 24 관리동 | G8: 051-832-0150 | H8: 57 | I8: 9 | J8: 20 | K8: 28 | L8: 0 | M8: 0 | N8: 0 | O8: 0 | P8: 0 | Q8: 0 | R8: 0 | S8: 10 | T8: =IF(COUNT(I8:S8)=0,"",SUM(I8:S8))
A9: 곰돌이어린이집 | B9: 어린이집 | C9: 가정 | D9: 강서구 | E9: 부산광역시 강서구 과학산단2로20번길 91 105동 103호 (지사동, 삼정그린코아) | G9: 051-972-8817 | H9: 20 | I9: 0 | J9: 0 | K9: 0 | L9: 0 | M9: 0 | N9: 0 | O9: 0 | P9: 0 | Q9: 0 | R9: 0 | S9: 0 | T9: =IF(COUNT(I9:S9)=0,"",SUM(I9:S9))
A10: 그린코아어린이집 | B10: 어린이집 | C10: 민간 | D10: 강서구 | E10: 부산광역시 강서구 과학산단2로20번길 91 (지사동, 삼정그린코아) | G10: 051-973-7399 | H10: 47 | I10: 5 | J10: 10 | K10: 21 | L10: 0 | M10: 0 | N10: 0 | O10: 3 | P10: 0 | Q10: 0 | R10: 0 | S10: 5 | T10: =IF(COUNT(I10:S10)=0,"",SUM(I10:S10))
A11: 글로벌새싹어린이집 | B11: 어린이집 | C11: 민간 | D11: 강서구 | E11: 부산광역시 강서구 명지오션시티9로 19 | G11: 051-271-1278 | H11: 128 | I11: 3 | J11: 15 | K11: 28 | L11: 45 | M11: 18 | N11: 18 | O11: 0 | P11: 0 | Q11: 0 | R11: 0 | S11: 16 | T11: =IF(COUNT(I11:S11)=0,"",SUM(I11:S11))
A12: 금강3차어린이집 | B12: 어린이집 | C12: 민간 | D12: 강서구 | E12: 부산광역시 강서구 명지국제5로 110 명지금강펜테리움센트럴파크3차아파트 302동 1층 관리동 보육시설 | G12: 051-208-3338 | H12: 38 | I12: 4 | J12: 8 | K12: 5 | L12: 0 | M12: 0 | N12: 0 | O12: 5 | P12: 0 | Q12: 0 | R12: 0 | S12: 6 | T12: =IF(COUNT(I12:S12)=0,"",SUM(I12:S12))
A13: 금강꿈동이어린이집 | B13: 어린이집 | C13: 민간 | D13: 강서구 | E13: 부산광역시 강서구 명지국제5로 109 명지2차 금강펜트리움센트럴파크 관리동 | G13: 051-204-5880 | H13: 49 | I13: 9 | J13: 16 | K13: 13 | L13: 0 | M13: 0 | N13: 0 | O13: 0 | P13: 0 | Q13: 0 | R13: 0 | S13: 5 | T13: =IF(COUNT(I13:S13)=0,"",SUM(I13:S13))
A14: 금강누리봄어린이집 | B14: 어린이집 | C14: 민간 | D14: 강서구 | E14: 부산광역시 강서구 명지국제5로 59 (명지동, 명지1차금강펜테리움센트럴파크아파트) | G14: 051-293-4628 | H14: 54 | I14: 9 | J14: 13 | K14: 20 | L14: 0 | M14: 0 | N14: 0 | O14: 0 | P14: 0 | Q14: 0 | R14: 0 | S14: 10 | T14: =IF(COUNT(I14:S14)=0,"",SUM(I14:S14))
A15: 금강아이뜰어린이집 | B15: 어린이집 | C15: 가정 | D15: 강서구 | E15: 부산광역시 강서구 명지국제5로 110 312동 101호 (명지동, 금강펜테리움센트럴파크3차) | G15: 051-204-3388 | H15: 19 | I15: 0 | J15: 0 | K15: 0 | L15: 0 | M15: 0 | N15: 0 | O15: 0 | P15: 0 | Q15: 0 | R15: 0 | S15: 0 | T15: =IF(COUNT(I15:S15)=0,"",SUM(I15:S15))
A16: 금강아이어린이집 | B16: 어린이집 | C16: 가정 | D16: 강서구 | E16: 부산광역시 강서구 명지국제5로 59 105동 102호(명지동, 금강펜테리움) | F16: http://jg8514@hanmail.net | G16: 051-907-8896 | H16: 20 | I16: 7 | J16: 5 | K16: 6 | L16: 0 | M16: 0 | N16: 0 | O16: 0 | P16: 0 | Q16: 0 | R16: 0 | S16: 3 | T16: =IF(COUNT(I16:S16)=0,"",SUM(I16:S16))
A17: 금강펜테리움어린이집 | B17: 어린이집 | C17: 민간 | D17: 강서구 | E17: 부산광역시 강서구 과학산단2로20번길 69 지사동, 금강펜테리움아파트 | G17: 051-973-1149 | H17: 45 | I17: 3 | J17: 16 | K17: 21 | L17: 0 | M17: 0 | N17: 0 | O17: 0 | P17: 0 | Q17: 0 | R17: 0 | S17: 10 | T17: =IF(COUNT(I17:S17)=0,"",SUM(I17:S17))
A18: 꿈나래어린이집 | B18: 어린이집 | C18: 가정 | D18: 강서구 | E18: 부산광역시 강서구 명지국제7로 37 205동 106호(명지동, 더샵명지퍼스트월드2단지) | G18: 051-201-0928 | H18: 20 | I18: 3 | J18: 10 | K18: 7 | L18: 0 | M18: 0 | N18: 0 | O18: 0 | P18: 0 | Q18: 0 | R18: 0 | S18: 4 | T18: =IF(COUNT(I18:S18)=0,"",SUM(I18:S18))
A19: 꿈담은어린이집 | B19: 어린이집 | C19: 가정 | D19: 강서구 | E19: 부산광역시 강서구 과학산단2로20번길 69 107동101호(지사동,지사금강펜테리움) | F19: https://www.instagram.com/ddc_s2 | G19: 051-973-0892 | H19: 18 | I19: 2 | J19: 0 | K19: 4 | L19: 0 | M19: 0 | N19: 0 | O19: 2 | P19: 0 | Q19: 0 | R19: 0 | S19: 4 | T19: =IF(COUNT(I19:S19)=0,"",SUM(I19:S19))
A20: 나무야어린이집 | B20: 어린이집 | C20: 가정 | D20: 강서구 | E20: 부산광역시 강서구 명지국제7로 111 110동 102호(명지동, 명지더웨스턴) | G20: 051-996-2028 | H20: 20 | I20: 5 | J20: 5 | K20: 0 | L20: 0 | M20: 0 | N20: 0 | O20: 8 | P20: 0 | Q20: 0 | R20: 0 | S20: 3 | T20: =IF(COUNT(I20:S20)=0,"",SUM(I20:S20))
A21: 낙동어린이집 | B21: 어린이집 | C21: 국공립 | D21: 강서구 | E21: 부산광역시 강서구 순아강변길 5 (명지동) | F21: http://www.ndswc.or.kr | G21: 051-271-0535 | H21: 43 | I21: 0 | J21: 15 | K21: 24 | L21: 0 | M21: 0 | N21: 0 | O21: 0 | P21: 0 | Q21: 0 | R21: 0 | S21: 5 | T21: =IF(COUNT(I21:S21)=0,"",SUM(I21:S21))
A22: 노리숲어린이집 | B22: 어린이집 | C22: 가정 | D22: 강서구 | E22: 부산광역시 강서구 명지국제7로 110 102동102호(명지동, 더 힐 시그니처) | G22: 051-208-1020 | H22: 20 | I22: 2 | J22: 9 | K22: 7 | L22: 0 | M22: 0 | N22: 0 | O22: 0 | P22: 0 | Q22: 0 | R22: 0 | S22: 4 | T22: =IF(COUNT(I22:S22)=0,"",SUM(I22:S22))
A23: 노블랜드에코어린이집 | B23: 어린이집 | C23: 민간 | D23: 강서구 | E23: 부산광역시 강서구 명지국제5로 11 (명지동, 대방노블랜드오션뷰2차아파트) | G23: 051-201-2871 | H23: 45 | I23: 14 | J23: 11 | K23: 10 | L23: 0 | M23: 0 | N23: 0 | O23: 0 | P23: 0 | Q23: 0 | R23: 0 | S23: 8 | T23: =IF(COUNT(I23:S23)=0,"",SUM(I23:S23))
A24: 녹산산단바른어린이집 | B24: 어린이집 | C24: 직장 | D24: 강서구 | E24: 부산광역시 강서구 녹산산단335로 11 (송정동) | G24: 051-831-5022 | H24: 99 | I24: 0 | J24: 9 | K24: 13 | L24: 23 | M24: 22 | N24: 19 | O24: 0 | P24: 0 | Q24: 0 | R24: 0 | S24: 12 | T24: =IF(COUNT(I24:S24)=0,"",SUM(I24:S24))
A25: 늘푸른어린이집 | B25: 어린이집 | C25: 가정 | D25: 강서구 | E25: 부산광역시 강서구 명지국제7로 111 108동 101호(명지1동, 명지더웨스턴) | G25: 051-204-8116 | H25: 20 | I25: 3 | J25: 10 | K25: 7 | L25: 0 | M25: 0 | N25: 0 | O25: 0 | P25: 0 | Q25: 0 | R25: 0 | S25: 5 | T25: =IF(COUNT(I25:S25)=0,"",SUM(I25:S25))
A26: 다솜어린이집 | B26: 어린이집 | C26: 가정 | D26: 강서구 | E26: 부산광역시 강서구 명지국제7로 110 109동 102호(명지동, 더 힐 시그니처) | G26: 070-8115-1022 | H26: 20 | I26: 6 | J26: 0 | K26: 7 | L26: 0 | M26: 0 | N26: 0 | O26: 6 | P26: 0 | Q26: 0 | R26: 0 | S26: 3 | T26: =IF(COUNT(I26:S26)=0,"",SUM(I26:S26))
A27: 대방1차아름드리어린이집 | B27: 어린이집 | C27: 민간 | D27: 강서구 | E27: 부산광역시 강서구 명지국제5로 30 관리동 어린이집(명지동, 대방노블랜드오션뷰1차아파트) | G27: 051-292-0029 | H27: 43 | I27: 9 | J27: 20 | K27: 8 | L27: 0 | M27: 0 | N27: 0 | O27: 0 | P27: 0 | Q27: 0 | R27: 0 | S27: 9 | T27: =IF(COUNT(I27:S27)=0,"",SUM(I27:S27))
A28: 대방아이어린이집 | B28: 어린이집 | C28: 가정 | D28: 강서구 | E28: 부산광역시 강서구 에코델타3로 120 114동 102호 | G28: 051-941-4911 | H28: 20 | I28: 9 | J28: 3 | K28: 0 | L28: 0 | M28: 0 | N28: 0 | O28: 0 | P28: 0 | Q28: 0 | R28: 0 | S28: 0 | T28: =IF(COUNT(I28:S28)=0,"",SUM(I28:S28))
A29: 대사라온어린이집 | B29: 어린이집 | C29: 민간 | D29: 강서구 | E29: 부산광역시 강서구 제도로 1166-11 3통5반 (강동동) | G29: 051-973-5254 | H29: 63 | I29: 0 | J29: 0 | K29: 0 | L29: 0 | M29: 0 | N29: 0 | O29: 0 | P29: 0 | Q29: 0 | R29: 0 | S29: 0 | T29: =IF(COUNT(I29:S29)=0,"",SUM(I29:S29))
A30: 대저어린이집 | B30: 어린이집 | C30: 사회복지법인 | D30: 강서구 | E30: 부산광역시 강서구 공항로767번나길 7 (대저2동) | G30: 051-973-4026 | H30: 72 | I30: 3 | J30: 16 | K30: 21 | L30: 0 | M30: 0 | N30: 0 | O30: 0 | P30: 0 | Q30: 0 | R30: 0 | S30: 0 | T30: =IF(COUNT(I30:S30)=0,"",SUM(I30:S30))
A31: 더베르힐어린이집 | B31: 어린이집 | C31: 국공립 | D31: 강서구 | E31: 부산광역시 강서구 에코델타5로 60 | G31: 051-941-4888 | H31: 68 | I31: 8 | J31: 35 | K31: 19 | L31: 0 | M31: 0 | N31: 0 | O31: 0 | P31: 0 | Q31: 0 | R31: 0 | S31: 5 | T31: =IF(COUNT(I31:S31)=0,"",SUM(I31:S31))
A32: 더샵해누리어린이집 | B32: 어린이집 | C32: 가정 | D32: 강서구 | E32: 부산광역시 강서구 명지국제2로 41 306동 106호(명지동, 더샵명지퍼스트월드3단지) | G32: 051-951-5200 | H32: 20 | I32: 5 | J32: 7 | K32: 7 | L32: 0 | M32: 0 | N32: 0 | O32: 0 | P32: 0 | Q32: 0 | R32: 0 | S32: 4 | T32: =IF(COUNT(I32:S32)=0,"",SUM(I32:S32))
A33: 도담도담어린이집 | B33: 어린이집 | C33: 가정 | D33: 강서구 | E33: 부산광역시 강서구 명지국제5로 165 804동 104호(스위트팰리스아파트) | G33: 051-988-8544 | H33: 20 | I33: 0 | J33: 0 | K33: 4 | L33: 0 | M33: 0 | N33: 0 | O33: 3 | P33: 0 | Q33: 0 | R33: 0 | S33: 3 | T33: =IF(COUNT(I33:S33)=0,"",SUM(I33:S33))
... A38: 라온제나어린이집 | B38: 어린이집 | C38: 사회복지법인 | D38: 강서구 | E38: 부산광역시 강서구 영강길 153-12 (명지동) | G38: 051-271-8303 | H38: 94 | I38: 0 | J38: 10 | K38: 21 | L38: 30 | M38: 9 | N38: 0 | O38: 0 | P38: 19 | Q38: 0 | R38: 0 | S38: 10 | T38: =IF(COUNT(I38:S38)=0,"",SUM(I38:S38))
A39: 롯데캐슬어린이집 | B39: 어린이집 | C39: 가정 | D39: 강서구 | E39: 부산광역시 강서구 명지오션시티11로 84 116동 104호(명지동, 롯데캐슬아파트) | F39: http://blog.naver.com/bskslottecastle | G39: 051-271-5800 | H39: 20 | I39: 2 | J39: 6 | K39: 5 | L39: 0 | M39: 0 | N39: 0 | O39: 0 | P39: 0 | Q39: 0 | R39: 0 | S39: 2 | T39: =IF(COUNT(I39:S39)=0,"",SUM(I39:S39))
A40: 리베어린이집 | B40: 어린이집 | C40: 가정 | D40: 강서구 | E40: 부산광역시 강서구 명지국제2로 41 302동 105호(명지동, 더샵명지퍼스트월드3단지) | G40: 051-271-1196 | H40: 20 | I40: 9 | J40: 5 | K40: 6 | L40: 0 | M40: 0 | N40: 0 | O40: 0 | P40: 0 | Q40: 0 | R40: 0 | S40: 5 | T40: =IF(COUNT(I40:S40)=0,"",SUM(I40:S40))
A41: 링컨어린이집 | B41: 어린이집 | C41: 민간 | D41: 강서구 | E41: 부산광역시 강서구 명지오션시티10로 16 퀸덤1차 링컨타운 211동 1층 (명지동) | G41: 051-997-1231 | H41: 30 | I41: 5 | J41: 9 | K41: 12 | L41: 0 | M41: 0 | N41: 0 | O41: 0 | P41: 0 | Q41: 0 | R41: 0 | S41: 4 | T41: =IF(COUNT(I41:S41)=0,"",SUM(I41:S41))
A42: 명지녹산산단 명지어린이집 | B42: 어린이집 | C42: 직장 | D42: 강서구 | E42: 부산광역시 강서구 명지오션시티11로 79 (명지동) | G42: 051-208-7009 | H42: 95 | I42: 3 | J42: 8 | K42: 13 | L42: 11 | M42: 0 | N42: 0 | O42: 5 | P42: 14 | Q42: 0 | R42: 0 | S42: 12 | T42: =IF(COUNT(I42:S42)=0,"",SUM(I42:S42))
A43: 명지더샵2단지어린이집 | B43: 어린이집 | C43: 국공립 | D43: 강서구 | E43: 부산광역시 강서구 명지국제7로 37 (명지동, 더샵명지퍼스트월드2단지) | G43: 051-291-0077 | H43: 56 | I43: 10 | J43: 15 | K43: 28 | L43: 0 | M43: 0 | N43: 0 | O43: 0 | P43: 0 | Q43: 0 | R43: 0 | S43: 15 | T43: =IF(COUNT(I43:S43)=0,"",SUM(I43:S43))
A44: 명지더샵3단지어린이집 | B44: 어린이집 | C44: 국공립 | D44: 강서구 | E44: 부산광역시 강서구 명지국제2로 41 (명지동, 더샵명지퍼스트월드3단지) | G44: 051-201-3403 | H44: 58 | I44: 0 | J44: 28 | K44: 28 | L44: 0 | M44: 0 | N44: 0 | O44: 0 | P44: 0 | Q44: 0 | R44: 0 | S44: 5 | T44: =IF(COUNT(I44:S44)=0,"",SUM(I44:S44))
...

Sheet 초등학교
A1: 학교명 | B1: 구분 | C1: 설립유형 | D1: 구/군 | E1: 주소 | F1: 공식 홈페이지 | G1: 전화번호 | H1: 공시연도 | I1: 1학년 | J1: 2학년 | K1: 3학년 | L1: 4학년 | M1: 5학년 | N1: 6학년 | O1: 특수학급 | P1: 순회학급 | Q1: 학생 합계 | R1: 비고
A2: 가락초등학교 | B2: 초등학교 | C2: 공립 | D2: 강서구 | E2: 부산광역시 강서구 호계로 41 | F2: http://school.busanedu.net/garak-e/main.do | G2: 051-972-8055 | H2: 2026 | I2: 1 | J2: 7 | K2: 1 | L2: 2 | M2: 3 | N2: 2 | O2: 3 | P2: 0 | Q2: =IF(COUNT(I2:P2)=0,"",SUM(I2:P2))
A3: 강서초등학교 | B3: 초등학교 | C3: 공립 | D3: 강서구 | E3: 부산광역시 강서구 에코델타2로 94 | F3: http://gangseoe.es.kr | G3: 051-366-1900 | H3: 2026 | I3: 111 | J3: 74 | K3: 93 | L3: 59 | M3: 58 | N3: 44 | O3: 7 | P3: 0 | Q3: =IF(COUNT(I3:P3)=0,"",SUM(I3:P3))
A4: 남명초등학교 | B4: 초등학교 | C4: 공립 | D4: 강서구 | E4: 부산광역시 강서구 명지오션시티11로 132 | F4: http://nam-myeong.es.kr/ | G4: 051-2600-200 | H4: 2026 | I4: 83 | J4: 108 | K4: 101 | L4: 120 | M4: 158 | N4: 136 | O4: 7 | P4: 0 | Q4: =IF(COUNT(I4:P4)=0,"",SUM(I4:P4))
A5: 녹명초등학교 | B5: 초등학교 | C5: 공립 | D5: 강서구 | E5: 부산광역시 강서구 낙동남로 617 | F5: http://nokmng.es.kr | G5: 051-971-5144 | H5: 2026 | I5: 16 | J5: 12 | K5: 19 | L5: 13 | M5: 18 | N5: 12 | O5: 5 | P5: 0 | Q5: =IF(COUNT(I5:P5)=0,"",SUM(I5:P5))
A6: 녹산초등학교 | B6: 초등학교 | C6: 공립 | D6: 강서구 | E6: 부산광역시 강서구 과학산단2로20번길 55 | F6: http://noksan.es.kr/ | G6: 051-979-1000 | H6: 2026 | I6: 128 | J6: 143 | K6: 142 | L6: 171 | M6: 171 | N6: 170 | O6: 7 | P6: 0 | Q6: =IF(COUNT(I6:P6)=0,"",SUM(I6:P6))
A7: 대사초등학교 | B7: 초등학교 | C7: 공립 | D7: 강서구 | E7: 부산광역시 강서구 낙동북로 73 | F7: http://psdaesa.es.kr | G7: 051-970-0300 | H7: 2026 | I7: 0 | J7: 1 | K7: 1 | L7: 0 | M7: 1 | N7: 0 | O7: 1 | P7: 0 | Q7: =IF(COUNT(I7:P7)=0,"",SUM(I7:P7))
A8: 대상초등학교 | B8: 초등학교 | C8: 공립 | D8: 강서구 | E8: 부산광역시 강서구 대저로 249 | F8: http://daesang.es.kr | G8: 051-971-6311 | H8: 2026 | I8: 6 | J8: 3 | K8: 7 | L8: 2 | M8: 8 | N8: 1 | O8: 5 | P8: 0 | Q8: =IF(COUNT(I8:P8)=0,"",SUM(I8:P8))
A9: 대저중앙초등학교 | B9: 초등학교 | C9: 공립 | D9: 강서구 | E9: 부산광역시 강서구 에코델타2로 23 | F9: http://school.busanedu.net/dj-joongang-e/main.do | G9: 051-605-1000 | H9: 2026 | I9: 250 | J9: 226 | K9: 201 | L9: 191 | M9: 184 | N9: 147 | O9: 6 | P9: 0 | Q9: =IF(COUNT(I9:P9)=0,"",SUM(I9:P9))
A10: 대저초등학교 | B10: 초등학교 | C10: 공립 | D10: 강서구 | E10: 부산광역시 강서구 대저로29번길 27 | F10: http://daejeo.es.kr | G10: 051-970-0200 | H10: 2026 | I10: 4 | J10: 0 | K10: 6 | L10: 2 | M10: 3 | N10: 4 | O10: 1 | P10: 0 | Q10: =IF(COUNT(I10:P10)=0,"",SUM(I10:P10))
A11: 덕두초등학교 | B11: 초등학교 | C11: 공립 | D11: 강서구 | E11: 부산광역시 강서구 공항로791번길 68 | F11: http://www.deokdu.es.kr/ | G11: 051-711-5120 | H11: 2026 | I11: 20 | J11: 33 | K11: 25 | L11: 31 | M11: 24 | N11: 28 | O11: 1 | P11: 0 | Q11: =IF(COUNT(I11:P11)=0,"",SUM(I11:P11))
A12: 명문초등학교 | B12: 초등학교 | C12: 공립 | D12: 강서구 | E12: 부산광역시 강서구 명지국제8로 195 | F12: http://myeongmun.es.kr | G12: 051-710-2114 | H12: 2026 | I12: 173 | J12: 199 | K12: 225 | L12: 219 | M12: 193 | N12: 156 | O12: 9 | P12: 0 | Q12: =IF(COUNT(I12:P12)=0,"",SUM(I12:P12))
A13: 명원초등학교 | B13: 초등학교 | C13: 공립 | D13: 강서구 | E13: 부산광역시 강서구 명지국제6로 147 | F13: http://school.busanedu.net/myoungwon-e/main.do | G13: 051-250-3300 | H13: 2026 | I13: 127 | J13: 175 | K13: 222 | L13: 193 | M13: 237 | N13: 230 | O13: 11 | P13: 0 | Q13: =IF(COUNT(I13:P13)=0,"",SUM(I13:P13))
... A119: 개금초등학교 | B119: 초등학교 | C119: 공립 | D119: 부산진구 | E119: 부산광역시 부산진구 가야대로443번길 25-10 | F119: http://kaegum.es.kr/ | G119: 051-893-0421 | H119: 2026 | I119: 72 | J119: 57 | K119: 70 | L119: 87 | M119: 104 | N119: 135 | O119: 10 | P119: 0 | Q119: =IF(COUNT(I119:P119)=0,"",SUM(I119:P119))
A120: 개림초등학교 | B120: 초등학교 | C120: 공립 | D120: 부산진구 | E120: 부산광역시 부산진구 백양대로320번길 40 | G120: 051-607-7001 | H120: 2026 | I120: 82 | J120: 80 | K120: 100 | L120: 108 | M120: 132 | N120: 111 | O120: 6 | P120: 0 | Q120: =IF(COUNT(I120:P120)=0,"",SUM(I120:P120))
A121: 개원초등학교 | B121: 초등학교 | C121: 공립 | D121: 부산진구 | E121: 부산광역시 부산진구 백양관문로77번길 17 | F121: http://kaewone.es.kr | G121: 051-927-9640 | H121: 2026 | I121: 44 | J121: 54 | K121: 62 | L121: 73 | M121: 74 | N121: 88 | O121: 7 | P121: 0 | Q121: =IF(COUNT(I121:P121)=0,"",SUM(I121:P121))
A122: 개포초등학교 | B122: 초등학교 | C122: 공립 | D122: 부산진구 | E122: 부산광역시 부산진구 백양대로208번길 9 | F122: http://www.gaepo.es.kr | G122: 051-930-8000 | H122: 2026 | I122: 18 | J122: 24 | K122: 27 | L122: 36 | M122: 45 | N122: 47 | O122: 5 | P122: 0 | Q122: =IF(COUNT(I122:P122)=0,"",SUM(I122:P122))
A123: 개화초등학교 | B123: 초등학교 | C123: 공립 | D123: 부산진구 | E123: 부산광역시 부산진구 개금본동로66번길 12-12 | F123: http://www.kae-hwa.es.kr | G123: 051-890-0100 | H123: 2026 | I123: 14 | J123: 10 | K123: 23 | L123: 21 | M123: 33 | N123: 30 | O123: 3 | P123: 0 | Q123: =IF(COUNT(I123:P123)=0,"",SUM(I123:P123))
A124: 당감초등학교 | B124: 초등학교 | C124: 공립 | D124: 부산진구 | E124: 부산광역시 부산진구 당감로 22-5 | F124: http://www.danggam.es.kr | G124: 051-896-0081 | H124: 2026 | I124: 15 | J124: 15 | K124: 21 | L124: 15 | M124: 32 | N124: 39 | O124: 5 | P124: 0 | Q124: =IF(COUNT(I124:P124)=0,"",SUM(I124:P124))
A125: 당평초등학교 | B125: 초등학교 | C125: 공립 | D125: 부산진구 | E125: 부산광역시 부산진구 백양대로136번길 26 | F125: http://www.dangpyung.es.kr | G125: 051-890-8500 | H125: 2026 | I125: 14 | J125: 23 | K125: 35 | L125: 25 | M125: 45 | N125: 44 | O125: 7 | P125: 0 | Q125: =IF(COUNT(I125:P125)=0,"",SUM(I125:P125))
A126: 동성초등학교 | B126: 초등학교 | C126: 사립 | D126: 부산진구 | E126: 부산광역시 부산진구 동성로 26 | F126: https://school.busanedu.net/ds-e | G126: 051-803-8987 | H126: 2026 | I126: 112 | J126: 112 | K126: 112 | L126: 112 | M126: 120 | N126: 120 | O126: 0 | P126: 0 | Q126: =IF(COUNT(I126:P126)=0,"",SUM(I126:P126))
A127: 동양초등학교 | B127: 초등학교 | C127: 공립 | D127: 부산진구 | E127: 부산광역시 부산진구 백양산로 99 | F127: http://school.busanedu.net/dong-yang-e/main.do | G127: 051-819-9103 | H127: 2026 | I127: 16 | J127: 18 | K127: 31 | L127: 28 | M127: 36 | N127: 31 | O127: 4 | P127: 0 | Q127: =IF(COUNT(I127:P127)=0,"",SUM(I127:P127))
A128: 동원초등학교 | B128: 초등학교 | C128: 공립 | D128: 부산진구 | E128: 부산광역시 부산진구 백양산로 43 | F128: http://www.pdw.es.kr | G128: 051-890-0200 | H128: 2026 | I128: 76 | J128: 92 | K128: 99 | L128: 92 | M128: 114 | N128: 108 | O128: 6 | P128: 0 | Q128: =IF(COUNT(I128:P128)=0,"",SUM(I128:P128))
A129: 동평초등학교 | B129: 초등학교 | C129: 공립 | D129: 부산진구 | E129: 부산광역시 부산진구 당감서로65번길 31 | F129: http://dongpyeong.es.kr | G129: 051-718-0100 | H129: 2026 | I129: 74 | J129: 92 | K129: 79 | L129: 86 | M129: 88 | N129: 81 | O129: 6 | P129: 0 | Q129: =IF(COUNT(I129:P129)=0,"",SUM(I129:P129))
A130: 부산진초등학교 | B130: 초등학교 | C130: 공립 | D130: 부산진구 | E130: 부산광역시 부산진구 범천로 30 | F130: http://pusanjin.es.kr | G130: 051-801-2800 | H130: 2026 | I130: 48 | J130: 52 | K130: 75 | L130: 78 | M130: 68 | N130: 60 | O130: 8 | P130: 0 | Q130: =IF(COUNT(I130:P130)=0,"",SUM(I130:P130))
A131: 부암초등학교 | B131: 초등학교 | C131: 공립 | D131: 부산진구 | E131: 부산광역시 부산진구 신천대로263번길 26 | F131: http://www.buam.es.kr | G131: 051-816-2675 | H131: 2026 | I131: 101 | J131: 104 | K131: 101 | L131: 122 | M131: 115 | N131: 131 | O131: 11 | P131: 0 | Q131: =IF(COUNT(I131:P131)=0,"",SUM(I131:P131))
A132: 부전초등학교 | B132: 초등학교 | C132: 공립 | D132: 부산진구 | E132: 부산광역시 부산진구 부전로65번길 25 | F132: https://school.busanedu.net/pspujun-e/main.do# | G132: 051-811-7800 | H132: 2026 | I132: 59 | J132: 62 | K132: 49 | L132: 61 | M132: 56 | N132: 62 | O132: 5 | P132: 0 | Q132: =IF(COUNT(I132:P132)=0,"",SUM(I132:P132))
... A181: 모라초등학교 | B181: 초등학교 | C181: 공립 | D181: 사상구 | E181: 부산광역시 사상구 모라로64번길 46 | F181: http://www.mora.es.kr/ | G181: 051-310-7400 | H181: 2026 | I181: 13 | J181: 17 | K181: 15 | L181: 11 | M181: 20 | N181: 27 | O181: 11 | P181: 0 | Q181: =IF(COUNT(I181:P181)=0,"",SUM(I181:P181))
A182: 모산초등학교 | B182: 초등학교 | C182: 공립 | D182: 사상구 | E182: 부산광역시 사상구 모라로110번길 93 | G182: 051-329-4000 | H182: 2026 | I182: 20 | J182: 41 | K182: 45 | L182: 45 | M182: 52 | N182: 45 | O182: 5 | P182: 0 | Q182: =IF(COUNT(I182:P182)=0,"",SUM(I182:P182))
A183: 사상초등학교 | B183: 초등학교 | C183: 공립 | D183: 사상구 | E183: 부산광역시 사상구 운산로 65 | F183: http://sasang.es.kr/ | G183: 051-330-5300 | H183: 2026 | I183: 47 | J183: 51 | K183: 63 | L183: 51 | M183: 55 | N183: 58 | O183: 12 | P183: 0 | Q183: =IF(COUNT(I183:P183)=0,"",SUM(I183:P183))
A184: 삼덕초등학교 | B184: 초등학교 | C184: 공립 | D184: 사상구 | E184: 부산광역시 사상구 삼덕로 24 | F184: http://www.samdok.es.kr | G184: 051-303-0242 | H184: 2026 | I184: 10 | J184: 12 | K184: 15 | L184: 22 | M184: 17 | N184: 12 | O184: 6 | P184: 0 | Q184: =IF(COUNT(I184:P184)=0,"",SUM(I184:P184))
A185: 서감초등학교 | B185: 초등학교 | C185: 공립 | D185: 사상구 | E185: 부산광역시 사상구 괘감로 64 | F185: http://seogam.es.kr/ | G185: 051-320-5800 | H185: 2026 | I185: 10 | J185: 21 | K185: 18 | L185: 16 | M185: 16 | N185: 20 | O185: 5 | P185: 0 | Q185: =IF(COUNT(I185:P185)=0,"",SUM(I185:P185))
A186: 엄궁초등학교 | B186: 초등학교 | C186: 공립 | D186: 사상구 | E186: 부산광역시 사상구 엄궁로191번길 23 | F186: http://www.omgung.es.kr/ | G186: 051-323-6840 | H186: 2026 | I186: 48 | J186: 57 | K186: 72 | L186: 87 | M186: 105 | N186: 102 | O186: 12 | P186: 0 | Q186: =IF(COUNT(I186:P186)=0,"",SUM(I186:P186))
A187: 주감초등학교 | B187: 초등학교 | C187: 공립 | D187: 사상구 | E187: 부산광역시 사상구 양지로 48 | F187: http://www.jugam.es.kr | G187: 051-320-3900 | H187: 2026 | I187: 93 | J187: 105 | K187: 81 | L187: 105 | M187: 101 | N187: 104 | O187: 12 | P187: 0 | Q187: =IF(COUNT(I187:P187)=0,"",SUM(I187:P187))
A188: 주양초등학교 | B188: 초등학교 | C188: 공립 | D188: 사상구 | E188: 부산광역시 사상구 백양대로 372-6 | F188: http://www.juyang.es.kr/ | G188: 051-329-1500 | H188: 2026 | I188: 28 | J188: 38 | K188: 37 | L188: 48 | M188: 51 | N188: 46 | O188: 6 | P188: 0 | Q188: =IF(COUNT(I188:P188)=0,"",SUM(I188:P188))
A189: 주학초등학교 | B189: 초등학교 | C189: 공립 | D189: 사상구 | E189: 부산광역시 사상구 가야대로366번길 120 | F189: http://www.juhak.es.kr | G189: 051-327-7471 | H189: 2026 | I189: 2 | J189: 4 | K189: 7 | L189: 6 | M189: 6 | N189: 6 | O189: 2 | P189: 0 | Q189: =IF(COUNT(I189:P189)=0,"",SUM(I189:P189))
A190: 창진초등학교 | B190: 초등학교 | C190: 공립 | D190: 사상구 | E190: 부산광역시 사상구 사상로223번길 100 | F190: http://www.changjin.es.kr/ | G190: 051-310-3400 | H190: 2026 | I190: 47 | J190: 68 | K190: 57 | L190: 67 | M190: 85 | N190: 59 | O190: 6 | P190: 0 | Q190: =IF(COUNT(I190:P190)=0,"",SUM(I190:P190))
A191: 학장초등학교 | B191: 초등학교 | C191: 공립 | D191: 사상구 | E191: 부산광역시 사상구 대동로 205 | F191: http://www.hakjang.es.kr/ | G191: 051-320-5701 | H191: 2026 | I191: 23 | J191: 33 | K191: 25 | L191: 37 | M191: 28 | N191: 33 | O191: 3 | P191: 0 | Q191: =IF(COUNT(I191:P191)=0,"",SUM(I191:P191))
A192: 학진초등학교 | B192: 초등학교 | C192: 공립 | D192: 사상구 | E192: 부산광역시 사상구 대동로 34-16 | F192: http://school.busanedu.net/hakjin-e | G192: 051-982-5000 | H192: 2026 | I192: 38 | J192: 38 | K192: 67 | L192: 65 | M192: 77 | N192: 69 | O192: 11 | P192: 0 | Q192: =IF(COUNT(I192:P192)=0,"",SUM(I192:P192))
A193: 감천초등학교 | B193: 초등학교 | C193: 공립 | D193: 사하구 | E193: 부산광역시 사하구 원양로 368-2 | F193: http://www.gam.es.kr | G193: 051-206-9482 | H193: 2026 | I193: 6 | J193: 15 | K193: 8 | L193: 20 | M193: 20 | N193: 13 | O193: 3 | P193: 0 | Q193: =IF(COUNT(I193:P193)=0,"",SUM(I193:P193))
...
